<robot name = "robot">
    <link name="Link0">
        <inertial>
            <origin xyz="0 0 0.8871037104473446" rpy="0 0 0"/>
            <mass value="1" />
            <inertia ixx="100" ixy="0" ixz="0" iyy="100" iyz="0" izz="100" />
        </inertial>
        <visual>
            <origin xyz="0 0 0.8871037104473446" rpy="0 0 0"/>
            <geometry>
                <box size="1.5257896326302387 1.5782735822799452 1.7742074208946892" />
            </geometry>
            <material name="Green">
                <color rgba="0.0 128.0 1.0 1.0"/>
            </material>
        </visual>
        <collision>
            <origin xyz="0 0 0.8871037104473446" rpy="0 0 0"/>
            <geometry>
                <box size="1.5257896326302387 1.5782735822799452 1.7742074208946892" />
            </geometry>
        </collision>
    </link>
    <joint name="Link0_Link1" type="revolute">
       <parent link="Link0"/>
       <child  link="Link1"/>
       <origin rpy="0 0 0" xyz="0 0.7891367911399726 0.8871037104473446" />
       <axis xyz="0 1 0"/>
       <limit effort="0.0" lower="-3.14159" upper="3.14159" velocity="0.0"/>
    </joint>
    <link name="Link1">
        <inertial>
            <origin xyz="0 0.3986634656928527 0" rpy="0 0 0"/>
            <mass value="1" />
            <inertia ixx="100" ixy="0" ixz="0" iyy="100" iyz="0" izz="100" />
        </inertial>
        <visual>
            <origin xyz="0 0.3986634656928527 0" rpy="0 0 0"/>
            <geometry>
                <box size="1.683145725207021 0.7973269313857054 1.5150936824649357" />
            </geometry>
            <material name="Green">
                <color rgba="0.0 128.0 1.0 1.0"/>
            </material>
        </visual>
        <collision>
            <origin xyz="0 0.3986634656928527 0" rpy="0 0 0"/>
            <geometry>
                <box size="1.683145725207021 0.7973269313857054 1.5150936824649357" />
            </geometry>
        </collision>
    </link>
    <joint name="Link1_Link2" type="revolute">
       <parent link="Link1"/>
       <child  link="Link2"/>
       <origin rpy="0 0 0" xyz="0 0.7973269313857054 0" />
       <axis xyz="0 1 0"/>
       <limit effort="0.0" lower="-3.14159" upper="3.14159" velocity="0.0"/>
    </joint>
    <link name="Link2">
        <inertial>
            <origin xyz="0 0.16762768139536338 0" rpy="0 0 0"/>
            <mass value="1" />
            <inertia ixx="100" ixy="0" ixz="0" iyy="100" iyz="0" izz="100" />
        </inertial>
        <visual>
            <origin xyz="0 0.16762768139536338 0" rpy="0 0 0"/>
            <geometry>
                <box size="1.551977667392573 0.33525536279072676 0.29752474395061307" />
            </geometry>
            <material name="Green">
                <color rgba="0.0 128.0 1.0 1.0"/>
            </material>
        </visual>
        <collision>
            <origin xyz="0 0.16762768139536338 0" rpy="0 0 0"/>
            <geometry>
                <box size="1.551977667392573 0.33525536279072676 0.29752474395061307" />
            </geometry>
        </collision>
    </link>
    <joint name="Link2_Link3" type="revolute">
       <parent link="Link2"/>
       <child  link="Link3"/>
       <origin rpy="0 0 0" xyz="0 0.33525536279072676 0" />
       <axis xyz="0 1 0"/>
       <limit effort="0.0" lower="-3.14159" upper="3.14159" velocity="0.0"/>
    </joint>
    <link name="Link3">
        <inertial>
            <origin xyz="0 0.24181840477524252 0" rpy="0 0 0"/>
            <mass value="1" />
            <inertia ixx="100" ixy="0" ixz="0" iyy="100" iyz="0" izz="100" />
        </inertial>
        <visual>
            <origin xyz="0 0.24181840477524252 0" rpy="0 0 0"/>
            <geometry>
                <box size="1.4489517145571766 0.48363680955048505 1.0672299755897956" />
            </geometry>
            <material name="Green">
                <color rgba="0.0 128.0 1.0 1.0"/>
            </material>
        </visual>
        <collision>
            <origin xyz="0 0.24181840477524252 0" rpy="0 0 0"/>
            <geometry>
                <box size="1.4489517145571766 0.48363680955048505 1.0672299755897956" />
            </geometry>
        </collision>
    </link>
    <joint name="Link3_Link4" type="revolute">
       <parent link="Link3"/>
       <child  link="Link4"/>
       <origin rpy="0 0 0" xyz="0 0.48363680955048505 0" />
       <axis xyz="0 1 0"/>
       <limit effort="0.0" lower="-3.14159" upper="3.14159" velocity="0.0"/>
    </joint>
    <link name="Link4">
        <inertial>
            <origin xyz="0 0.3980254947311478 0" rpy="0 0 0"/>
            <mass value="1" />
            <inertia ixx="100" ixy="0" ixz="0" iyy="100" iyz="0" izz="100" />
        </inertial>
        <visual>
            <origin xyz="0 0.3980254947311478 0" rpy="0 0 0"/>
            <geometry>
                <box size="0.23320692054957776 0.7960509894622956 0.6257586957054899" />
            </geometry>
            <material name="Green">
                <color rgba="0.0 128.0 1.0 1.0"/>
            </material>
        </visual>
        <collision>
            <origin xyz="0 0.3980254947311478 0" rpy="0 0 0"/>
            <geometry>
                <box size="0.23320692054957776 0.7960509894622956 0.6257586957054899" />
            </geometry>
        </collision>
    </link>
</robot>