<robot name = "robot">
    <link name="Link0">
        <inertial>
            <origin xyz="0 0 0.24582313832608538" rpy="0 0 0"/>
            <mass value="1" />
            <inertia ixx="100" ixy="0" ixz="0" iyy="100" iyz="0" izz="100" />
        </inertial>
        <visual>
            <origin xyz="0 0 0.24582313832608538" rpy="0 0 0"/>
            <geometry>
                <box size="0.26930194887184805 1.5951329881470557 0.49164627665217076" />
            </geometry>
            <material name="Blue">
                <color rgba="0.0 0.0 255.0 1.0"/>
            </material>
        </visual>
        <collision>
            <origin xyz="0 0 0.24582313832608538" rpy="0 0 0"/>
            <geometry>
                <box size="0.26930194887184805 1.5951329881470557 0.49164627665217076" />
            </geometry>
        </collision>
    </link>
    <joint name="Link0_Link1" type="revolute">
       <parent link="Link0"/>
       <child  link="Link1"/>
       <origin rpy="0 0 0" xyz="0.13465097443592403 0 0.547413055316397" />
       <axis xyz="0 1 0"/>
       <limit effort="0.0" lower="-3.14159" upper="3.14159" velocity="0.0"/>
    </joint>
    <link name="Link1">
        <inertial>
            <origin xyz="0.772623244169301 0 0" rpy="0 0 0"/>
            <mass value="1" />
            <inertia ixx="100" ixy="0" ixz="0" iyy="100" iyz="0" izz="100" />
        </inertial>
        <visual>
            <origin xyz="0.772623244169301 0 0" rpy="0 0 0"/>
            <geometry>
                <box size="1.545246488338602 0.8379783736586159 1.094826110632794" />
            </geometry>
            <material name="Green">
                <color rgba="0.0 128.0 1.0 1.0"/>
            </material>
        </visual>
        <collision>
            <origin xyz="0.772623244169301 0 0" rpy="0 0 0"/>
            <geometry>
                <box size="1.545246488338602 0.8379783736586159 1.094826110632794" />
            </geometry>
        </collision>
    </link>
</robot>